Job 12277379.pbspl1.nas.nasa.gov started on Thu Dec 02 11:48:13 PST 2021
The job requested the following resources:
    ncpus=16
    place=scatter:excl
    walltime=02:00:00

PBS set the following environment variables:
        FORT_BUFFERED = 1
                   TZ = PST8PDT

On r633i1n1:
removing old scheduler directory
creating new scheduler directory
as a script
Hola, dask has been set up!!!
ConnectionRefusedError: [Errno 111] Connection refused

The above exception was the direct cause of the following exception:

Traceback (most recent call last):
  File "/home6/amondal/.conda/envs/xmitgcm3/lib/python3.8/site-packages/distributed/comm/core.py", line 285, in connect
    comm = await asyncio.wait_for(
  File "/home6/amondal/.conda/envs/xmitgcm3/lib/python3.8/asyncio/tasks.py", line 494, in wait_for
    return fut.result()
  File "/home6/amondal/.conda/envs/xmitgcm3/lib/python3.8/site-packages/distributed/comm/tcp.py", line 391, in connect
    convert_stream_closed_error(self, e)
  File "/home6/amondal/.conda/envs/xmitgcm3/lib/python3.8/site-packages/distributed/comm/tcp.py", line 124, in convert_stream_closed_error
    raise CommClosedError(
distributed.comm.core.CommClosedError: in <distributed.comm.tcp.TCPConnector object at 0x2aaacb4ccdc0>: ConnectionRefusedError: [Errno 111] Connection refused

The above exception was the direct cause of the following exception:

Traceback (most recent call last):
  File "script15_multicore_3month_test_new.py", line 45, in <module>
    client = Client('127.0.0.1:8786')
  File "/home6/amondal/.conda/envs/xmitgcm3/lib/python3.8/site-packages/distributed/client.py", line 753, in __init__
    self.start(timeout=timeout)
  File "/home6/amondal/.conda/envs/xmitgcm3/lib/python3.8/site-packages/distributed/client.py", line 966, in start
    sync(self.loop, self._start, **kwargs)
  File "/home6/amondal/.conda/envs/xmitgcm3/lib/python3.8/site-packages/distributed/utils.py", line 354, in sync
    raise exc.with_traceback(tb)
  File "/home6/amondal/.conda/envs/xmitgcm3/lib/python3.8/site-packages/distributed/utils.py", line 337, in f
    result[0] = yield future
  File "/home6/amondal/.conda/envs/xmitgcm3/lib/python3.8/site-packages/tornado/gen.py", line 762, in run
    value = future.result()
  File "/home6/amondal/.conda/envs/xmitgcm3/lib/python3.8/site-packages/distributed/client.py", line 1056, in _start
    await self._ensure_connected(timeout=timeout)
  File "/home6/amondal/.conda/envs/xmitgcm3/lib/python3.8/site-packages/distributed/client.py", line 1113, in _ensure_connected
    comm = await connect(
  File "/home6/amondal/.conda/envs/xmitgcm3/lib/python3.8/site-packages/distributed/comm/core.py", line 309, in connect
    raise IOError(
OSError: Timed out trying to connect to tcp://127.0.0.1:8786 after 10 s

____________________________________________________________________
Job Resource Usage Summary for 12277379.pbspl1.nas.nasa.gov

    CPU Time Used            : 00:00:14
    Real Memory Used         : 333320kb
    Walltime Used            : 00:01:24
    Exit Status              : 0

    Number of CPUs Requested : 16
    Walltime Requested       : 02:00:00

    Execution Queue          : devel
    Charged To               : s1353

    Job Stopped              : Thu Dec  2 11:50:00 2021
____________________________________________________________________
